package pokecube.core.world.gen.village.buildings;

import java.util.List;
import java.util.Random;

import net.minecraft.init.Blocks;
import net.minecraft.util.EnumFacing;
import net.minecraft.world.World;
import net.minecraft.world.gen.structure.StructureBoundingBox;
import net.minecraft.world.gen.structure.StructureComponent;
import net.minecraft.world.gen.structure.StructureVillagePieces.PieceWeight;
import net.minecraft.world.gen.structure.StructureVillagePieces.Start;
import pokecube.core.PokecubeItems;
import thut.api.maths.Vector3;

public class ComponentPokeCentre extends ComponentVillageBase {

    public static ComponentPokeCentre buildComponent(PieceWeight villagePiece, Start startPiece,
			List<StructureComponent> pieces, Random random, int p1, int p2, int p3,
			EnumFacing facing, int p5)
    {
//        StructureBoundingBox structureboundingbox = StructureBoundingBox.getComponentToAddBoundingBox(par3, par4, par5, 9, 8, 9, par6);
    	StructureBoundingBox structureboundingbox = StructureBoundingBox.getComponentToAddBoundingBox(p1, p2, p3, 0, 0, 0, 9, 8, 9, facing);
        return canVillageGoDeeper(structureboundingbox) && StructureComponent.findIntersecting(pieces, structureboundingbox) == null ? new ComponentPokeCentre(startPiece, p5, random, structureboundingbox, facing) : null;
    }
    private int averageGroundLevel = -1;
    public boolean spawn = false;
    
    public int centre = 0;
    
	public ComponentPokeCentre()
    {
    	
    }
	
    public ComponentPokeCentre(Start par1ComponentVillageStartPiece, int par2, Random par3Random, StructureBoundingBox par4StructureBoundingBox, EnumFacing par5) {
		super(par1ComponentVillageStartPiece, par2, par3Random, par4StructureBoundingBox, par5);
        this.coordBaseMode = par5;
        this.boundingBox = par4StructureBoundingBox;
	}

	@Override
	public boolean addComponentParts(World world, Random random, StructureBoundingBox structureboundingbox) {
		averageGroundLevel = -1;
		if(this.boundingBox==null)
			this.boundingBox = structureboundingbox;
		
		if (this.averageGroundLevel < 0&&!spawn)
        {
            this.averageGroundLevel = this.getAverageGroundLevel(world, structureboundingbox);

            if (this.averageGroundLevel < 0)
            {
                return true;
            }

            this.boundingBox.offset(0, this.averageGroundLevel - this.boundingBox.maxY + 5, 0);
        }
		//LoggerPokecube.logMessage("Creating PokeCentre");
        
        //Hollow it out
        this.fillWithMetaBlocks(world, structureboundingbox, 0, 0, 0, 8, 8, 8, Blocks.AIR, 0,false);
        
        //Roof
        this.fillWithMetaBlocks(world, structureboundingbox, 0, 6, 0, 8, 6, 8, Blocks.STAINED_HARDENED_CLAY, 14,false);
        this.fillWithMetaBlocks(world, structureboundingbox, 1, 6, 1, 7, 7, 7, Blocks.STAINED_HARDENED_CLAY, 14,false);
        this.fillWithMetaBlocks(world, structureboundingbox, 2, 6, 2, 6, 8, 6, Blocks.STAINED_HARDENED_CLAY, 14,false);
        this.fillWithMetaBlocks(world, structureboundingbox, 1, 6, 1, 7, 6, 7, Blocks.PLANKS, 1,  false);
        
        //Floor
        this.fillWithMetaBlocks(world, structureboundingbox, 0, 0, 0, 8, 2, 8, Blocks.COBBLESTONE, 0, false);
        this.fillWithMetaBlocks(world, structureboundingbox, 1, 2, 1, 7, 2, 7, Blocks.PLANKS, 1, false);
        
        //Walls
        this.fillWithMetaBlocks(world, structureboundingbox, 8, 3, 0, 8, 5, 8, Blocks.PLANKS, 1, false);//RIGHT WALL
        this.fillWithMetaBlocks(world, structureboundingbox, 0, 3, 8, 8, 5, 8, Blocks.PLANKS, 1, false);//LEFT WALL
        this.fillWithMetaBlocks(world, structureboundingbox, 0, 3, 0, 0, 5, 8, Blocks.PLANKS, 1, false);//BACK WALL
        this.fillWithMetaBlocks(world, structureboundingbox, 0, 3, 0, 8, 5, 0, Blocks.PLANKS, 1, false);//FRONT WALL
        //CORNERS
        this.fillWithMetaBlocks(world, structureboundingbox, 0, 3, 0, 0, 5, 0, Blocks.LOG, 1, false);
        this.fillWithMetaBlocks(world, structureboundingbox, 0, 3, 8, 0, 5, 8, Blocks.LOG, 1, false);
        this.fillWithMetaBlocks(world, structureboundingbox, 8, 3, 8, 8, 5, 8, Blocks.LOG, 1, false);
        this.fillWithMetaBlocks(world, structureboundingbox, 8, 3, 0, 8, 5, 0, Blocks.LOG, 1, false);

        //Windows
        this.fillWithMetaBlocks(world, structureboundingbox, 2, 4, 0, 2, 4, 0, Blocks.GLASS_PANE, 0, false);//front
        this.fillWithMetaBlocks(world, structureboundingbox, 6, 4, 0, 6, 4, 0, Blocks.GLASS_PANE, 0, false);//front
        this.fillWithMetaBlocks(world, structureboundingbox, 8, 4, 2, 8, 4, 3, Blocks.GLASS_PANE, 0, false);//left
        this.fillWithMetaBlocks(world, structureboundingbox, 8, 4, 5, 8, 4, 6, Blocks.GLASS_PANE, 0, false);//left
        this.fillWithMetaBlocks(world, structureboundingbox, 0, 4, 2, 0, 4, 3, Blocks.GLASS_PANE, 0, false);//right
        this.fillWithMetaBlocks(world, structureboundingbox, 0, 4, 5, 0, 4, 6, Blocks.GLASS_PANE, 0, false);//right
        
        //carpet
        this.fillWithMetaBlocks(world, structureboundingbox, 3, 3, 2, 5, 3, 2, Blocks.CARPET, 0, false);//white
        this.fillWithMetaBlocks(world, structureboundingbox, 3, 3, 3, 5, 3, 3, Blocks.CARPET, 15, false);//black
        this.fillWithMetaBlocks(world, structureboundingbox, 3, 3, 4, 5, 3, 4, Blocks.CARPET, 14, false);//red
        this.placeBlockAtCurrentPosition(world, Blocks.CARPET, 7, 4, 3, 3, structureboundingbox);//grey 
        
        centre = structureboundingbox.minY+3;
        
        
        //Ceiling Light
        this.placeBlockAtCurrentPosition(world, Blocks.REDSTONE_BLOCK, 0, 4, 7, 3, structureboundingbox);//redstone to power lamp
        this.placeBlockAtCurrentPosition(world, Blocks.LIT_REDSTONE_LAMP, 0, 4, 6, 3, structureboundingbox);//lamp

        //counter
        this.fillWithMetaBlocks(world, structureboundingbox, 3, 3, 5, 5, 3, 5, Blocks.DOUBLE_STONE_SLAB, 0, false);//front
        this.placeBlockAtCurrentPosition(world, Blocks.DOUBLE_STONE_SLAB, 0, 6, 3, 6, structureboundingbox);//side
        this.placeBlockAtCurrentPosition(world, Blocks.DOUBLE_STONE_SLAB, 0, 2, 3, 6, structureboundingbox);//side
        this.fillWithMetaBlocks(world, structureboundingbox, 2, 2, 6, 6, 2, 7, Blocks.DOUBLE_STONE_SLAB, 0, false);//floor
        
        //accessories
        this.placeBlockAtCurrentPosition(world, PokecubeItems.getBlock("pc"), getMetaWithOffset(PokecubeItems.getBlock("pc"), 0), 6, 3, 5, structureboundingbox);//PC Base
        this.placeBlockAtCurrentPosition(world, PokecubeItems.getBlock("pc"), getMetaWithOffset(PokecubeItems.getBlock("pc"), 8), 6, 4, 5, structureboundingbox);//PC Top
        this.placeBlockAtCurrentPosition(world, PokecubeItems.getBlock("tradingtable"), 0, 2, 3, 5, structureboundingbox);//tradeTable
        this.placeBlockAtCurrentPosition(world, PokecubeItems.pokecenter, 1, 4, 3, 7, structureboundingbox);//healingTable
        this.placeBlockAtCurrentPosition(world, Blocks.REDSTONE_TORCH, 0, 4, 2, 7, structureboundingbox);//healingTable
        //DOOR
        this.placeDoorCurrentPosition(world, structureboundingbox, random, 4, 3, 0, coordBaseMode.rotateY());
        
        //Stairs
        Vector3 here = toAbsolute(4, 2, -1);
        if((here.isAir(world)||here.getBlockState(world).getBlock().isCollidable())&&!here.offset(EnumFacing.DOWN).isAir(world))
        	this.placeBlockAtCurrentPosition(world, Blocks.STONE_STAIRS, 
        		this.getMetaWithOffset(Blocks.STONE_STAIRS, 3), 4, 2, -1, structureboundingbox);//
    	this.placeBlockAtCurrentPosition(world, Blocks.AIR, 0, 4, 3, -1, structureboundingbox);//
    	this.placeBlockAtCurrentPosition(world, Blocks.AIR, 0, 4, 4, -1, structureboundingbox);//
    	this.placeBlockAtCurrentPosition(world, Blocks.AIR, 0, 4, 5, -1, structureboundingbox);//
    	this.placeBlockAtCurrentPosition(world, Blocks.AIR, 0, 4, 6, -1, structureboundingbox);//

        for (int l = 0; l < 9; ++l)
        {
            for (int i1 = 0; i1 < 9; ++i1)
            {
                this.clearCurrentPositionBlocksUpwards(world, i1, 9, l, structureboundingbox);
                this.fillDownwards(world, Blocks.COBBLESTONE, 0, i1, -1, l, structureboundingbox);//this.getBiomeSpecificBlock(Blocks.COBBLESTONE, 0)
            }
        }
        if(!spawn)
        	this.spawnVillagers(world, structureboundingbox, 1, 1, 2, 1);
        else
        	spawn = false;
        return true;
	}
}
